Workbook

Sheet 表土剥离和回覆质量报验表
G1: 表土剥离与回覆 | Q1: 工序/ | T1: 单元工程施工质量报验单
B3: ( | O3: 承包 | Q3: [ | U3: ] 质报 | Z3: 号)
B4: 合同名称： | H4: 布拖县2024年高标准农田建设项目（增发国债） | Y4: 合同编号：
B6: 致（监理机构）： | H6: 中浩宇项目管理有限公司
D7: =表土玻璃和回覆质量评定表!M6 -> 2024HD10地块-@file_num田块 | K7: =G1 -> 表土剥离与回覆 | P7: □ | Q7: 工序/ | S7:  | T7: 单元工程已按合同要求完成施工，经自检合格，报请贵
C8: 方复核。
E9: 附： | G9: □ | X9: 工序施工质量评定表 | AM9: 0
G10: □ | X10: 工序施工质量检查、检测记录 | AM10: 0
G11: □ | I11: =G1 -> 表土剥离与回覆 | X11: 单元工程施工质量评定表 | AM11: 1
G12: □ | X12: 单元工程施工质量检查、检测记录 | AM12: 0
P17: 承包人：（现场机构名称及盖章）
P18: 质检负责人：（签名）
P19: 日 期： | T19: 年 月 日
B20: 监理机构 意 见 | F20: 复核结果：
G22: □ | H22: 同意进入下一工序 | U22: □ | W22: 不同意进入下一工序
G23: □ | H23: 同意进入下一单元工程 | U23: □ | W23: 不同意进入下一单元工程
F25: 附件：监理复核支持材料。
P27: 监理机构：（名称及盖章）
P28: 监理工程师：（签名）
P29: 日 期： | T29: 年 月 日
B30: 说明：本表一式 | J30: 份，由承包人填写。监理机构复核后，监理机构 | AA30: 份，返承包人 | AH30: 份。

Sheet 表土玻璃和回覆质量评定表
B2: 表土剥离与回覆单元工程质量检验评定表
B3: 项目名称： | F3: 布拖县2024年高标准农田建设项目（增发国债） | Y3: 合同编号：
B4: 单位（子单位）工程名称或编码 | M4: 土地平整工程 | W4: 工程量
B5: 分部工程名称或编码 | M5: 2024HD10地块土地平整 | W5: 检验日期 | AA5: 年 月 日
B6: 单元工程名称 | M6: 2024HD10地块-@file_num田块 | Y6: 表土剥离与回覆
B7: 项次 | D7: 检查项目 | M7: 质量标准 | AA7: 检验结果
B8: 1 | D8: 原耕作层土壤见证取样 | M8: 表土剥离前，对原耕作层土壤进行见证取样，送具备资质的检测单位对土壤的N、P、K及有机质其他参数含量进行检测。检测数据作为表土回填后土壤有机质恢复程度的复测数据，具体检测内容可按现行。四川省工程建设规范《建设占用耕地表土剥离再利用技术标准》DGTJ08-2275-2018的相关要求执行 | AA8: 符合要求
B9: 2 | D9: 表土剥离范围、剥离厚度 | M9: 表土剥离范围、剥离厚度应符合设计要求 | AA9: 符合要求
B10: 3 | D10: 表土回填后，应对原耕作层土壤的有机质含量 | M10: 表土回填后，应对原耕作层土壤的有机质含量进行第二次检测，原耕作层土壤有机质恢复程度不应低于85% | AA10: 符合要求
B11: 项次 | D11: 检测项目 | M11: 允许偏差 | Q11: 检测值 | AA11: 合格率 （%）
B12: 1 | D12: 表土剥离厚度 | M12: 不小于设计值 | Q12: @int<30,33>.cell | R12: @int<30,33>.cell | S12: @int<30,33>.cell | T12: @int<30,33>.cell | U12: @int<30,33>.cell | V12: @int<30,33>.cell | W12: @int<30,33>.cell | X12: @int<30,33>.cell | Y12: @int<30,33>.cell | Z12: @int<30,33>.cell | AA12: =(COUNTIF(Q12:Z12,">=30")/COUNTA(Q12:Z12))*100% -> 0
B13: 2 | D13: 表土回填范围 | M13: ≥90% | Q13: @int<90,93>.cell | R13: @int<90,93>.cell | S13: @int<90,93>.cell | T13: @int<90,93>.cell | U13: @int<90,93>.cell | V13: @int<90,93>.cell | W13: @int<90,93>.cell | X13: @int<90,93>.cell | Y13: @int<90,93>.cell | Z13: @int<90,93>.cell | AA13: =(COUNTIF(Q13:Z13,">=90")/COUNTA(Q13:Z13))*100% -> 0
B14: 3 | D14: 表土回填厚度 | M14: 不小于设计值 | Q14: @int<30,33>.cell | R14: @int<30,33>.cell | S14: @int<30,33>.cell | T14: @int<30,33>.cell | U14: @int<30,33>.cell | V14: @int<30,33>.cell | W14: @int<30,33>.cell | X14: @int<30,33>.cell | Y14: @int<30,33>.cell | Z14: @int<30,33>.cell | AA14: =(COUNTIF(Q14:Z14,">=30")/COUNTA(Q14:Z14))*100% -> 0
B15: 4 | D15: 土壤有机质恢复程度 | M15: ≥85% | Q15: @int<83,90>.cell | R15: @int<83,90>.cell | S15: @int<83,90>.cell | T15: @int<83,90>.cell | U15: @int<83,90>.cell | V15: @int<83,90>.cell | W15: @int<83,90>.cell | X15: @int<83,90>.cell | Y15: @int<83,90>.cell | Z15: @int<83,90>.cell | AA15: =(COUNTIF(Q15:Z15,">85")/COUNTA(Q15:Z15))*100% -> 0
B16: 5 | D16: 砾石、碎石等粗颗粒含量 | M16: ≤10% | Q16: @int<7,12>.cell | R16: @int<7,12>.cell | S16: @int<7,12>.cell | T16: @int<7,12>.cell | U16: @int<7,12>.cell | V16: @int<7,12>.cell | W16: @int<7,12>.cell | X16: @int<7,12>.cell | Y16: @int<7,12>.cell | Z16: @int<7,12>.cell | AA16: =(COUNTIF(Q16:Z16,"<=10")/COUNTA(Q16:Z16))*100% -> 0
B17: 共检测 | E17: 50 | G17: 点，其中合格 | K17: =SUM(AA12:AH16)*10 -> 0 | M17: 点，合格率 | Q17: =AVERAGE(AA12:AH16)*100 -> 0 | S17: %
B19: 评定结论：
H20: □ | I20: 合格 | M20: □ | N20: 不合格
B21: 施工单位（盖章） | R21: 监理单位（盖章）
B22: 质检员： | R22: 监理工程师：
B23: 质量（技术）负责人：
J24: 年 月 日 | Z24: 年 月 日
B25: 注：检验日期为终检日期，由施工单位负责填写。

Sheet 土方开挖报验表
G3: =M9 -> 土方开挖 | P3: 工序/ | T3: 单元工程施工质量报验单
B5: ( | O5: 承包 | Q5: [ | U5: ] 质报 | Z5: 号)
B6: 合同名称： | H6: 布拖县2024年高标准农田建设项目（增发国债） | Y6: 合同编号：
B8: 致（监理构）： | H8: 中浩宇项目管理有限公司
E9: =土方开挖评定表!L7 -> 2024HD10地块-@file_num田块 | M9: =土方开挖评定表!V7 -> 土方开挖 | P9: □ | Q9: 工序/ | S9:  | T9: 单元工程已按合同要求完成施工，经自检合格，报请贵
C10: 方复核。
E11: 附： | G11: □ | X11: 工序施工质量评定表 | AM11: 0
G12: □ | X12: 工序施工质量检查、检测记录 | AM12: 0
G13: □ | I13: =土方开挖评定表!V7 -> 土方开挖 | X13: 单元工程施工质量评定表 | AM13: 1
G14: □ | X14: 单元工程施工质量检查、检测记录 | AM14: 0
P19: 承包人：（现场机构名称及盖章）
P20: 质检负责人：（签名）
P21: 日 期： | T21: 年 月 日
B22: 监理机构 意 见 | F22: 复核结果：
G24: □ | H24: 同意进入下一工序 | U24: □ | W24: 不同意进入下一工序
G25: □ | H25: 同意进入下一单元工程 | U25: □ | W25: 不同意进入下一单元工程
F27: 附件：监理复核支持材料。
P29: 监理机构：（名称及盖章）
P30: 监理工程师：（签名）
P31: 日 期： | T31: 年 月 日
B32: 说明：本表一式 | J32: 份，由承包人填写。监理机构复核后，监理机构 | AA32: 份，返承包人 | AH32: 份。

Sheet 土方开挖评定表
K2: 布拖县2024年高标准农田建设项目（增发国债） | AI2: 工程
J3: 土方开挖单元工程施工质量验收评定表
B5: 单位工程名称 | L5: =表土玻璃和回覆质量评定表!M4 -> 土地平整工程 | Z5: 单元工程量
B6: 分部工程名称 | L6: =表土玻璃和回覆质量评定表!M5 -> 2024HD10地块土地平整 | Z6: 施工单位 | AF6: 四川华浩建筑工程有限公司
B7: 单元工程名称、部位 | L7: =表土玻璃和回覆质量评定表!M6 -> 2024HD10地块-@file_num田块 | V7: 土方开挖 | Z7: 施工日期 | AF7: 年 月 日 | AN7: - | AO7: 年 月 日
B8: 项次 | F8: 工序名称（或编号） | X8: 工序质量验收评定等级
B9: 1 | F9: 表土及土质岸坡清理 | X9: 合格
B10: 2 | F10: △软基或土质岸坡开挖 | X10: 合格
B11: 施工 单位 自评 意见 | F11: 各工序施工质量全部合格，其中优良工序占 | Y11: 0 | AC11: %，且主要工序达到 | AM11: 合格 | AQ11: 等级，各项
F12: 报验资料 | J12: 合格 | N12: SL 631-2012的要求。
F13: 单元工程质量等级评定为： | S13: 合格 | AJ13: 。
F15: （签字，加盖公章） | AN15: 年 月 日
B16: 监理 单位 复核 意见 | F16: 经抽查并查验相关检验报告和检验资料，各工序施工质量全部合格，其中优良工序占 | AT16: %，
F17: 且主要工序达到 | Q17: 等级，各项报验资料 | AD17: SL 631-2012的要求。
F18: 单元工程质量等级评定为： | AL18: 。
F20: （签字，加盖公章） | AN20: 年 月 日
B21: 注：本表所填“单元工程量”不作为施工单位工程量结算计量的依据。

Sheet 表土及土质岸坡清理工序
A1: 布拖2024年高标准农田建设项目（增发国债）工程
A2: 表1.1.1 表土及土质岸坡清理工序施工质量验收评定表（未找到对应设计值）
A3: 单位工程名称 | D3: 均质土坝工程 | G3: 工序编号 | I3: /
A4: 分部工程名称 | D4: 坝基开挖与处理 | G4: 施工单位
A5: 单元工程名称、部位 | D5: 土方开挖 桩号：0+100～0+150 ▽55.300m | G5: 施工日期 | I5: 年 月 日～ 年 月 日
A6: 项次 | C6: 检验项目 | E6: 质量要求 | H6: 检查记录 | N6: 合格数 | O6: 合格率
A7: 主控项目 | B7: 1 | C7: 表土清理 | E7: 树木、草皮、树根、乱石、坟墓以及各种建筑物全部清除；水井、泉眼、地道、坑窖等洞穴的处理符合设计要求 | H7: 树木、草皮、树根已经清除，无坟墓、水井、泉眼等，检查结果完全符合质量要求。 | N7: / | O7: 1
B8: 2 | C8: 不良土质的处理 | E8: 淤泥、腐殖质土、泥炭土全部清除；对风化岩石、坡积物、残积物、滑坡体、粉土、细砂等处理符合设计要求 | H8: 淤泥、腐殖质土、泥炭土全部清除，无其他不良土质，检查结果完全符合质量要求。 | N8: / | O8: 1
B9: 3 | C9: 地质坑、孔处理 | E9: 构筑物基础区范围内的地质探孔、竖井、试坑的处理符合设计要求；回填材料质量满足设计要求 | H9: 地质探孔在桩号0+120处，孔直径2m，采用回填灌浆处理，检查结果完全符合质量要求。 | N9: / | O9: 1
A10: 一般项目 | B10: 1 | C10: 清理范围 | E10: 人工清理 | F10: 满足设计要求。长、宽边线允许偏差0~50cm | H10: / | N10: / | O10: /
E11: 机械清理 | F11: 满足设计要求，长、宽边线允许偏差0~100cm | H11: 从设计中心测量，清理长度：25m，宽度：15m，实测结果为： 长度：@float.2<25,26>，@float.2<25,26>，@float.2<25,26>，@float.2<25,26>，@float.2<25,26>，@float.2<25,26>，@float.2<25,26>，@float.2<25,26>，@float.2<25,26>，@float.2<25,26> 宽度：@float.2<15,16>，@float.2<15,16>，@float.2<15,16>，@float.2<15,16>，@float.2<15,16>，@float.2<15,16>，@float.2<15,16>，@float.2<15,16>，@float.2<15,16>，@float.2<15,16> | N11: 20 | O11: 1
B12: 2 | C12: 土质岸边坡度 | E12: 不陡于设计边坡（1:0.5） | H12: 1:@float.1<2.0,2.5>，1:@float.1<2.0,2.5>，1:@float.1<2.0,2.5>，1:@float.1<2.0,2.5>，1:@float.1<2.0,2.5> | N12: 5 | O12: 0.833
A14: 施工 单位 自评 意见 | C14: 主控项目检验点全部合格，一般项目逐项检验点的合格率均不小于 70 %，且不合格点不集中分布。
C15: 各项报验资料 符合 SL631—2012的要求。
C16: 工序质量等级评定为： 合格 。
C21: (签字，加盖公章） 年 月 日
A22: 监理 单位 复核 意见 | C22: 经复核，主控项目检验点全部合格，一般项目逐项检验点的合格率均不小于 %，且不合格点不集中分布。
C23: 各项报验资料 SL631—2012的要求。
C24: 工序质量等级评定为： 。
C28: (签字，加盖公章） 年 月 日

Sheet 软基或土质岸坡开挖工序
A1: 布拖2024年高标准农田建设项目（增发国债）工程
A2: 表1.1.2 软基或土质岸坡开挖工序施工质量验收评定表（未找到对应设计值）
A3: 单位工程名称 | F3: 均质土坝工程 | H3: 工序编号 | J3: /
A4: 分部工程名称 | F4: 坝基开挖与处理 | H4: 施工单位 | J4: 四川华浩建筑工程有限公司
A5: 单元工程名称、部位 | F5: 土方开挖 桩号：0+100～0+150 ▽55.300m | H5: 施工日期 | J5: 年 月 日～ 年 月 日
A6: 项次 | C6: 检验项目 | G6: 质量要求 | I6: 检查记录 | O6: 合格数 | P6: 合格率
A7: 主控项目 | B7: 1 | C7: 保护层开挖 | G7: 保护层开挖方式应符合设计要求，在接近建基面时，宜使用小型机具或人工挖除，不应扰动建基面以下的原地基 | I7: 保护层开挖厚度50cm，采用人工开挖，对原地基无扰动，检查结果完全符合质量要求。 | O7: / | P7: 1
B8: 2 | C8: 建基面处理 | G8: 构筑物软基和土质岸坡开挖面平顺。软基和土质岸坡与土质构筑物接触时，采用斜面连接，无台阶、急剧变坡及反坡 | I8: 建基面处理采用斜面连接，无台阶、急剧变坡及反坡，检查结果完全符合质量要求 | O8: / | P8: 1
B9: 3 | C9: 渗水处理 | G9: 构筑物基础区及土质岸坡渗水(含泉眼）妥善引排或封堵，建基面清洁无积水 | I9: 无渗水点，建基面清洁无积水，检查结果完全符合质量要求 | O9: / | P9: 1
A10: 一般项目 | B10: 1 | C10: 基 坑 断 面 尺 寸 及 开 挖 面 平 整 度 | D10: 无 结 构 要 求 或 无 配 筋 | E10: 长或宽不大于10m | G10: 符合设计要求，允许偏差为 －10～20cm（设计宽390cm） | I10: / | O10: / | P10: /
E12: 长或宽大于10m | G12: 符合设计要求，允许偏差为 －20～30cm | I12: / | O12: / | P12: /
E14: 坑（槽）底部标高 | G14: 符合设计要求，允许偏差为 －10～20cm（设计标高1458.14-1458.01） | I14: / | O14: / | P14: /
E16: 垂直或斜面平整度 | G16: 符合设计要求，允许偏差为20cm | I16: / | O16: / | P16: /
D18: 有 结 构 要 求 有 配 筋 预 埋 件 | E18: 长或宽不大于10m | G18: 符合设计要求，允许偏差为 0～20cm | I18: / | O18: / | P18: /
E20: 长或宽大于10m | G20: 符合设计要求，允许偏差为 0～30cm | I20: 长度：@float.2<50,50.3>，@float.2<50,50.3>，@float.2<50,50.3>，@float.2<50,50.3>，@float.2<50,50.3>，@float.2<50,50.3>，@float.2<50,50.3>，@float.2<50,50.3>，@float.2<50,50.3>； 宽度：@float.2<20,20.3>，@float.2<20,20.3>，@float.2<20,20.3>，@float.2<20,20.3>，@float.2<20,20.3>，@float.2<20,20.3>，@float.2<20,20.3>，@float.2<20,20.3>，@float.2<20,20.3> | O20: 18 | P20: 0.9
G21: 50m×20m
E22: 坑（槽）底部标局 | G22: 符合设计要求，允许偏差为 0～20cm | I22: @float.2<55.3,55.5>，@float.2<55.3,55.5>，@float.2<55.3,55.5>，@float.2<55.3,55.5>，@float.2<55.3,55.5>，@float.2<55.3,55.5>，@float.2<55.3,55.5>，@float.2<55.3,55.5> | O22: 8 | P22: 0.8
G23: 高程55.30m
E24: 斜面平整度 | G24: 符合设计要求，允许偏差为15cm | I24: @int<7,15>，@int<7,15>，@int<7,15>，@int<7,15>，@int<7,15>，@int<7,15>，@int<7,15>，@int<7,15> | O24: 8 | P24: 0.8
A26: 施工 单位 自评 意见 | C26: 主控项目检验点全部合格，一般项目逐项检验点的合格率均不小于 70 %，且不合格点不集中分布。
C27: 各项报验资料 符合 SL631—2012的要求。
C28: 工序质量等级评定为： 合格 。
C31: (签字，加盖公章） 年 月 日
A32: 监理 单位 复核 意见 | C32: 经复核，主控项目检验点全部合格，一般项目逐项检验点的合格率均不小于 %，且不合格点不集中分布。
C33: 各项报验资料 SL631—2012的要求。
C34: 工序质量等级评定为： 。
C36: (签字，加盖公章） 年 月 日

Sheet 土料填筑质量报验单
G1: 土料填筑 | Q1: 工序/ | T1: 单元工程施工质量报验单
B3: ( | O3: 承包 | Q3: [ | U3: ] 质报 | Z3: 号)
B4: 合同名称： | H4: 布拖县2024年高标准农田建设项目（增发国债） | Y4: 合同编号：
B6: 致（监理机构）： | H6: 中浩宇项目管理有限公司
E7: =土方开挖评定表!L7 -> 2024HD10地块-@file_num田块 | M7: 土料填筑 | P7: □ | Q7: 工序/ | S7:  | T7: 单元工程已按合同要求完成施工，经自检合格，报请贵
C8: 方复核。
E9: 附： | G9: □ | X9: 工序施工质量评定表 | AM9: 0
G10: □ | X10: 工序施工质量检查、检测记录 | AM10: 0
G11: □ | I11: =G1 -> 土料填筑 | X11: 单元工程施工质量评定表 | AM11: 1
G12: □ | X12: 单元工程施工质量检查、检测记录 | AM12: 0
P17: 承包人：（现场机构名称及盖章）
P18: 质检负责人：（签名）
P19: 日 期： | T19: 年 月 日
B20: 监理机构 意 见 | F20: 复核结果：
G22: □ | H22: 同意进入下一工序 | U22: □ | W22: 不同意进入下一工序
G23: □ | H23: 同意进入下一单元工程 | U23: □ | W23: 不同意进入下一单元工程
F25: 附件：监理复核支持材料。
P27: 监理机构：（名称及盖章）
P28: 监理工程师：（签名）
P29: 日 期： | T29: 年 月 日
B30: 说明：本表一式 | J30: 份，由承包人填写。监理机构复核后，监理机构 | AA30: 份，返承包人 | AH30: 份。

Sheet 土料填筑评定表
K2: 布拖县2024年高标准农田建设项目（增发国债） | AI2: 工程
J3: 土料填筑单元工程施工质量验收评定表
B5: 单位工程名称 | L5: 土地平整工程 | Z5: 单元工程量
B6: 分部工程名称 | L6: =土方开挖评定表!L6 -> 2024HD10地块土地平整 | Z6: 施工单位 | AF6: 四川华浩建筑工程有限公司
B7: 单元工程名称、部位 | L7: =土方开挖评定表!L7 -> 2024HD10地块-@file_num田块 | V7: 土料填筑 | Z7: 施工日期 | AF7: 年 月 日 | AN7: - | AO7: 年 月 日
B8: 项次 | F8: 工序名称（或编号） | X8: 工序质量验收评定等级
B9: 1 | F9: 结合面处理 | X9: 合格
B10: 2 | F10: 卸料及铺填 | X10: 合格
B11: 3 | F11: △土料压实 | X11: 合格
B12: 4 | F12: 接缝处理 | X12: 合格
B13: 施工 单位 自评 意见 | F13: 各工序施工质量全部合格，其中优良工序占 | Y13: 0 | AC13: %，且主要工序达到 | AM13: 合格 | AQ13: 等级，各项
F14: 报验资料 | J14: 符合 | N14: SL 631-2012的要求。
F15: 单元工程质量等级评定为： | S15: 合格 | AJ15: 。
F17: （签字，加盖公章） | AN17: 年 月 日
B18: 监理 单位 复核 意见 | F18: 经抽查并查验相关检验报告和检验资料，各工序施工质量全部合格，其中优良工序占 | AT18: %，
F19: 且主要工序达到 | Q19: 等级，各项报验资料 | AD19: SL 631-2012的要求。
F20: 单元工程质量等级评定为： | AL20: 。
F22: （签字，加盖公章） | AN22: 年 月 日
B23: 注：本表所填“单元工程量”不作为施工单位工程量结算计量的依据。

Sheet 土料填筑结合面处理工序
J1: 布拖2024年高标准农田建设项目（增发国债） | AH1: 工程
A2: 表 1.6.1 | I2: 土料填筑结合面处理工序施工质量验收评定表 | AO2: （未找到对应设计值）
A3: 单位工程名称 | K3: 均质土坝工程 | Z3: 工序编号
A4: 分部工程名称 | K4: 坝体填筑 | Z4: 施工单位 | AE4: 四川华浩建筑工程有限公司
A5: 单元工程名称、部位 | K5: 土料填筑 桩号：0+100～0+150 ▽131.500～131.800m | Z5: 施工日期 | AE5: 年 月 日 | AM5: - | AN5: 年 月 日
A6: 项次 | E6: 检验项目 | K6: 质量要求 | V6: 检查记录 | AP6: 合格数 | AS6: 合格率
A7: 主 控 项 目 | C7: 1 | E7: 建基面地基压实 | G7: 黏性土、砾质土地基土层 | K7: 压实度等指标符合设计要求 | V7: 压实度检测全部合格，检测点20个，检查结果完全符合质量要求，检测结果见附件。 | AP7: 20 | AS7: 1
G9: 无黏性土地基土层 | K9: 相对密实度符合设计要求 | V9: / | AP9: / | AS9: 1
C11: 2 | E11: 土质建基面刨毛 | K11: 土质地基表面刨毛3～5cm，层面刨毛均匀细致，无团块、空白 | V11: 土质地基表面刨毛3～5cm，层面刨毛均匀细致，无团块、空白，检查结果完全符合质量要求。 | AP11: / | AS11: 100%
C12: 3 | E12: 岩面和混凝土面处理 | K12: 与土质防渗体结合的岩面或混凝土面，无浮渣、污物杂物，无乳皮粉尘、油垢，无局部积水等。铺填前涂刷浓泥浆或黏土水泥砂浆，涂刷均匀，无空白，且回填及时，无风干现象 | V12: / | AP12: / | AS12: /
K13: 混凝土面 | M13: 涂刷厚度为3～5mm，铺浆厚度允许偏差0～2mm | V13: / | AP13: / | AS13: /
K15: 裂隙岩面 | M15: 涂刷厚度为5～10mm，铺浆厚度允许偏差0～2mm | V15: / | AP15: / | AS15: /
A17: 一 般 项 目 | C17: 1 | E17: 层间结合面 | K17: 上下层铺土的结合层面无砂砾、无杂物、表面松土、湿润均匀、无积水 | V17: 上下层铺土的结合层面无砂砾、无杂物、表面松土、湿润均匀、无积水，检查结果符合质量要求。 | AP17: / | AS17: 0.9
C18: 2 | E18: 涂刷浆液质量 | K18: 浆液稠度适宜、均匀无团块，材料配比误差不大于10% | V18: 浆液稠度适宜、均匀无团块，材料配比误差为 3％～5％，检查结果符合质量要求。 | AP18: / | AS18: 0.9
A19: 施工 单位 自评 意见 | E19: 主控项目检验点全部合格，一般项目逐项检验点的合格率均不小于 | AG19: 90 | AK19: %，且不合格点不集中分
E20: 布，各项报验资料 | M20: 符合 | R20: SL 631-2012的要求。
E21: 工序质量等级评定为： | P21: 优良 | AI21: 。
E23: （签字，加盖公章） | AM23: 年 月 日
A24: 监理 单位 复核 意见 | E24: 经复核，主控项目检验点全部合格，一般项目逐项检验点的合格率均不小于 | AO24: %，且不合格点不
E25: 集中分布，各项报验资料 | U25: SL 631-2012的要求。
E26: 工序质量等级评定为： | AI26: 。
E28: （签字，加盖公章） | AM28: 年 月 日

Sheet 土料填筑卸料及铺填工序
B2: 布拖2024年高标准农田建设项目（增发国债）工程
B3: 表 1.6.2 | J3: 土料填筑卸料及铺填工序施工质量验收评定表 | AP3: （未找到对应设计值）
B4: 单位工程名称 | L4: 均质土坝工程 | AA4: 工序编号
B5: 分部工程名称 | L5: 坝体填筑 | AA5: 施工单位 | AF5: 四川华浩建筑工程有限公司
B6: 单元工程名称、部位 | L6: 土料填筑 桩号：0+100～0+150 ▽131.500～131.800m | AA6: 施工日期 | AF6: 年 月 日 | AN6: - | AO6: 年 月 日
B7: 项次 | F7: 检验项目 | L7: 质量要求 | W7: 检查记录 | AQ7: 合格数 | AT7: 合格率
B8: 主 控 项 目 | D8: 1 | F8: 卸料 | L8: 卸料、平料符合设计要求，均衡上升。施工面平整、土料分区清晰，上下层分段位置错开 | W8: 倒退法卸料、土料分区清晰，上下层分段位置错开，检查结果完全符合质量要求。 | AQ8: / | AT8: 1
D10: 2 | F10: 铺填 | L10: 铺填应有富裕量，防渗铺盖在坝体以内部分应与心墙或斜墙同时铺填。铺料表面应保持湿润，符合施工含水量 | W10: 上下游坝坡铺填有富裕量，防渗铺盖在坝体以内部分与心墙同时铺填。铺料表面湿润，符合施工含水量，检查结果完全符合质量要求。 | AQ10: / | AT10: 1
B11: 一 般 项 目 | D11: 1 | F11: 结合部土料铺填 | L11: 防渗体与地基(包括齿槽)、岸坡、溢洪道边墙、坝下埋管及混凝土齿墙等结合部位的土料铺填，无架空现象。土料厚度均匀，表面平整，无团块、无粗粒集中，边线整齐 | W11: 防渗体与溢洪道边墙土料铺填无架空现象。土料厚度均匀，表面平整，无团块、无粗粒集中，边线整齐，检查结果符合质量要求。 | AQ11: / | AT11: 0.9
D12: 2 | F12: 铺土厚度 | L12: 铺土厚度均匀，符合设计要求，允许偏差为-5～0cm | W12: @int<28,30>，@int<28,30>，@int<28,30> | AQ12: 3 | AT12: 1
L13: 设计值：
D14: 3 | F14: 铺填边线 | H14: 人工施工 | L14: 铺填边线应有一定宽裕度，压实削坡后坝体铺填边线满足0～10cm要求 | W14: / | AQ14: / | AT14: /
H16: 机械施工 | L16: 铺填边线应有一定宽裕度，压实削坡后坝体铺填边线满足0～30cm要求 | W16: / | AQ16: / | AT16: /
B18: 施工 单位 自评 意见 | F18: 主控项目检验点全部合格，一般项目逐项检验点的合格率均不小于 | AH18: 90 | AL18: %，且不合格点不集中分
F19: 布，各项报验资料 | N19: 符合 | S19: SL 631-2012的要求。
F20: 工序质量等级评定为： | Q20: 优良 | AJ20: 。
F22: （签字，加盖公章） | AN22: 年 月 日
B23: 监理 单位 复核 意见 | F23: 经复核，主控项目检验点全部合格，一般项目逐项检验点的合格率均不小于 | AP23: %，且不合格点不
F24: 集中分布，各项报验资料 | V24: SL 631-2012的要求。
F25: 工序质量等级评定为： | AJ25: 。
F27: （签字，加盖公章） | AN27: 年 月 日

Sheet 土料填筑土料压实工序
B2: 布拖2024年高标准农田建设项目（增发国债）工程
B3: 表 1.6.3 | J3: 土料填筑土料压实工序施工质量验收评定表 | AP3: （未找到对应设计值）
B4: 单位工程名称 | L4: 均质土坝工程 | AA4: 工序编号
B5: 分部工程名称 | L5: 坝体填筑 | AA5: 施工单位
B6: 单元工程名称、部位 | L6: 土料填筑 桩号：0+100～0+150 ▽131.500～131.800m | AA6: 施工日期 | AF6: 年 月 日 | AN6: - | AO6: 年 月 日
B7: 项次 | F7: 检验项目 | L7: 质量要求 | Z7: 检查记录 | AQ7: 合格数 | AT7: 合格率
B8: 主 控 项 目 | D8: 1 | F8: 碾压参数 | L8: 压实机具的型号、规格、碾压遍数、碾压速度、碾压振动频率、振幅和加水量应符合碾压试验确定的参数值 | Z8: 现场采用自行式凸块振动碾静压2遍，振动压6遍，碾压速度2km/h，碾压振动频率30Hz，其他参数均符合碾压试验确定的参数值，检查结果完全符合质量要求。 | AQ8: / | AT8: 1
D10: 2 | F10: 压实质量 | L10: 1级、2级坝和高坝的压实度不低于98% | Z10: @float.1<98,98.5>，@float.1<98,98.5>，@float.1<98,98.5> | AQ10: / | AT10: 1
L11: 3级中低坝及3级以下中坝的压实度不低于96% | Z11: / | AQ11: / | AT11: /
L12: 土料的含水量应控制在最优量的 -2%～3%之间 | Z12: @float.1<1,3>%，@float.1<1,3>%，@float.1<1,3>% | AQ12: 3 | AT12: 1
L13: 取样合格率不小于90% | Z13: / | AQ13: / | AT13: /
L14: 不合格试样不应集中，且不低于压实度设计值的98% | Z14: / | AQ14: / | AT14: /
D15: 3 | F15: 压实土料的渗透系数 | L15: 符合设计要求 | Z15: / | AQ15: / | AT15: /
B16: 一 般 项 目 | D16: 1 | F16: 碾压搭接带宽度 | L16: 垂直碾压方向 | R16: 搭接宽度0.3～0.5m | Z16: @float.1<1,1.5>，@float.1<1,1.5>，@float.1<1,1.5>，@float.1<1,1.5>，@float.1<1,1.5>，@float.1<1,1.5> | AQ16: 6 | AT16: 1
L17: 顺碾压方向 | R17: 搭接宽度1.0～1.5m | Z17: @float.1<0.3,0.4>，@float.1<0.3,0.4>，@float.1<0.3,0.4>，@float.1<0.3,0.4>，@float.1<0.3,0.4>，@float.1<0.3,0.4> | AQ17: 6 | AT17: 1
D18: 2 | F18: 碾压面处理 | L18: 碾压表面平整，无漏压，个别有弹簧、起皮、脱空、剪力破坏部位的处理符合设计要求 | Z18: 碾压表面平整，无漏压 | AQ18: / | AT18: 0.9
B20: 施工 单位 自评 意见 | F20: 主控项目检验点全部合格，一般项目逐项检验点的合格率均不小于 | AH20: 90 | AL20: %，且不合格点不集中分
F21: 布，各项报验资料 | N21: 符合 | S21: SL 631-2012的要求。
F22: 工序质量等级评定为： | Q22: 优良 | AJ22: 。
F24: （签字，加盖公章） | AN24: 年 月 日
B25: 监理 单位 复核 意见 | F25: 经复核，主控项目检验点全部合格，一般项目逐项检验点的合格率均不小于 | AP25: %，且不合格点不
F26: 集中分布，各项报验资料 | V26: SL 631-2012的要求。
F27: 工序质量等级评定为： | AJ27: 。
F29: （签字，加盖公章） | AN29: 年 月 日

Sheet 土料填筑接缝处理工序
J1: 布拖2024年高标准农田建设项目（增发国债） | AH1: 工程
A2: 表 1.6.4 | I2: 土料填筑接缝处理工序施工质量验收评定表 | AO2: （未找到对应设计值）
A3: 单位工程名称 | K3: 均质土坝工程 | Z3: 工序编号
A4: 分部工程名称 | K4: 坝体填筑 | Z4: 施工单位 | AE4: 四川华浩建筑工程有限公司
A5: 单元工程名称、部位 | K5: 土料填筑 桩号：0+100～0+150 ▽131.500～131.800m | Z5: 施工日期 | AE5: 年 月 日 | AM5: - | AN5: 年 月 日
A6: 项次 | E6: 检验项目 | K6: 质量要求 | V6: 检查记录 | AP6: 合格数 | AS6: 合格率
A7: 主 控 项 目 | C7: 1 | E7: 结合坡面 | K7: 斜墙和心墙内不应留有纵向接缝。防渗体及均质坝的横向接坡不应陡于1：3，其高差应符合设计要求，与岸坡结合坡度应符合设计要求。均质坝纵向接缝斜坡坡度和平台宽度应满足稳定要求，平台间高差不大于15m | V7: 无纵、横向接缝，与岸坡结合坡度为1：3，符合设计要求，与混凝土溢洪道边墙及土质岸坡结合处1.5m～2m，小范围内用小型机具压实，与上下游反滤料及坝壳料骑缝碾压密实，检查结果完全符合质量要求。 | AP7: / | AS7: 1
C8: 2 | E8: 结合坡面碾压 | K8: 结合坡面填土碾压密实，层面平整、无拉裂和起皮现象 | Q8: 设计压实度0.96 | V8: @float.2<0.96,0.98>，@float.2<0.96,0.98>，@float.2<0.96,0.98>，@float.2<0.96,0.98>，@float.2<0.96,0.98> | AP8: / | AS8: 1
A9: 一 般 项 目 | C9: 1 | E9: 结合坡面填土 | K9: 填土质量符合设计要求，铺土均匀、表面平整，无团块、无风干 | V9: 填土质量符合设计要求，铺土均匀、表面平整，无团块、无风干，检查结果符合质量要求。 | AP9: / | AS9: 0.9
C10: 2 | E10: 结合坡面处理 | K10: 纵横接缝的坡面削坡、润湿、刨毛等处理符合设计要求 | V10: 检查30个点，纵横接缝的坡面削坡、润湿、刨毛等处理符合设计要求，检查结果符合质量要求。 | AP10: / | AS10: 0.9
A11: 施工 单位 自评 意见 | E11: 主控项目检验点全部合格，一般项目逐项检验点的合格率均不小于 | AG11: 90 | AK11: %，且不合格点不集中分
E12: 布，各项报验资料 | M12: 符合 | R12: SL 631-2012的要求。
E13: 工序质量等级评定为： | P13: 优良 | AI13: 。
E15: （签字，加盖公章） | AM15: 年 月 日
A16: 监理 单位 复核 意见 | E16: 经复核，主控项目检验点全部合格，一般项目逐项检验点的合格率均不小于 | AO16: %，且不合格点不
E17: 集中分布，各项报验资料 | U17: SL 631-2012的要求。
E18: 工序质量等级评定为： | AI18: 。
E20: （签字，加盖公章） | AM20: 年 月 日

Sheet 田埂修筑报验表
G1: 田埂修筑 | Q1: 工序/ | T1: 单元工程施工质量报验单
B3: ( | O3: 承包 | Q3: [ | U3: ] 质报 | Z3: 号)
B4: 合同名称： | H4: 布拖县2024年高标准农田建设项目（增发国债） | Y4: 合同编号：
B6: 致（监理机构）： | H6: 中浩宇项目管理有限公司
E7: =土方开挖评定表!L7 -> 2024HD10地块-@file_num田块 | M7: =G1 -> 田埂修筑 | P7: □ | Q7: 工序/ | S7:  | T7: 单元工程已按合同要求完成施工，经自检合格，报请贵
C8: 方复核。
E9: 附： | G9: □ | X9: 工序施工质量评定表 | AM9: 0
G10: □ | X10: 工序施工质量检查、检测记录 | AM10: 0
G11: □ | I11: 田埂修筑 | X11: 单元工程施工质量评定表 | AM11: 1
G12: □ | X12: 单元工程施工质量检查、检测记录 | AM12: 0
P17: 承包人：（现场机构名称及盖章）
P18: 质检负责人：（签名）
P19: 日 期： | T19: 年 月 日
B20: 监理机构 意 见 | F20: 复核结果：
G22: □ | H22: 同意进入下一工序 | U22: □ | W22: 不同意进入下一工序
G23: □ | H23: 同意进入下一单元工程 | U23: □ | W23: 不同意进入下一单元工程
F25: 附件：监理复核支持材料。
P27: 监理机构：（名称及盖章）
P28: 监理工程师：（签名）
P29: 日 期： | T29: 年 月 日
B30: 说明：本表一式 | J30: 份，由承包人填写。监理机构复核后，监理机构 | AA30: 份，返承包人 | AH30: 份。

Sheet 田埂修筑质量评定表
J2: 田埂修筑 | Q2: 单元工程质量检验评定表
B3: 项目名称： | F3: 布拖县2024年高标准农田建设项目（增发国债） | Z3: 合同编号：
B4: 单位（子单位）工程名称或编码 | M4: =表土玻璃和回覆质量评定表!M4 -> 土地平整工程 | W4: 工程量
B5: 分部工程名称或编码 | M5: =表土玻璃和回覆质量评定表!M5 -> 2024HD10地块土地平整 | W5: 检验日期 | AA5: 年 月 日
B6: 单元工程名称 | M6: =表土玻璃和回覆质量评定表!M6 -> 2024HD10地块-@file_num田块 | Y6: =J2 -> 田埂修筑
B7: 项次 | D7: 检查项目 | M7: 质量标准 | AA7: 检验结果
B8: 1 | D8: 田埂的位置 | M8: 田埂的位置应符合设计要求 | AA8: 符合要求
B9: 2 | D9: 田埂土料 | M9: 田埂土料应符合设计要求 | AA9: 符合要求
B10: 3 | D10: 田埂截面尺寸偏差 | M10: 田埂截面尺寸偏差应符合设计要求 | AA10: 符合要求
B11: 4 | D11: 田埂质量 | M11: 田埂应密实，不应有松散、塌陷等质量问题 | AA11: 符合要求
B12: 项次 | D12: 检测项目 | M12: 允许偏差 （mm） | Q12: 检测值 | AA12: 合格率 （%）
B13: 1 | D13: 田埂断面尺寸 | M13: ±30 | Q13: @int<-30,30>.cell | R13: @int<-30,30>.cell | S13: @int<-30,30>.cell | T13: @int<-30,30>.cell | U13: @int<-30,30>.cell | V13: @int<-30,30>.cell | W13: @int<-30,30>.cell | X13: @int<-30,30>.cell | Y13: @int<-30,30>.cell | Z13: @int<-30,30>.cell | AA13: =(COUNTIF(Q13:Z13,">=-30")-COUNTIF(Q13:Z13,">30"))/COUNT(Q13:Z13) -> #DIV/0!
B14: 2 | D14: 顺直度 | M14: ±80 | Q14: @int<-80,80>.cell | R14: @int<-80,80>.cell | S14: @int<-80,80>.cell | T14: @int<-80,80>.cell | U14: @int<-80,80>.cell | V14: @int<-80,80>.cell | W14: @int<-80,80>.cell | X14: @int<-80,80>.cell | Y14: @int<-80,80>.cell | Z14: @int<-80,80>.cell | AA14: =(COUNTIF(Q14:Z14,">=-80")-COUNTIF(Q14:Z14,">80"))/COUNT(Q14:Z14) -> #DIV/0!
B15: 3 | D15: 田埂顶面高程 | M15: ±50 | Q15: @int<-50,50>.cell | R15: @int<-50,50>.cell | S15: @int<-50,50>.cell | T15: @int<-50,50>.cell | U15: @int<-50,50>.cell | V15: @int<-50,50>.cell | W15: @int<-50,50>.cell | X15: @int<-50,50>.cell | Y15: @int<-50,50>.cell | Z15: @int<-50,50>.cell | AA15: =(COUNTIF(Q15:Z15,">=-50")-COUNTIF(Q15:Z15,">50"))/COUNT(Q15:Z15) -> #DIV/0!
B16: 共检测 | E16: 30 | G16: 点，其中合格 | K16: =SUM(AA13:AH15)*10 -> #DIV/0! | M16: 点，合格率 | Q16: =AVERAGE(AA14:AH15)*100 -> #DIV/0! | S16: %
B18: 评定结论：
H19: □ | I19: 合格 | M19: □ | N19: 不合格
B20: 施工单位（盖章） | R20: 监理单位（盖章）
B21: 质检员： | R21: 监理工程师：
B22: 质量（技术）负责人：
J23: 年 月 日 | Z23: 年 月 日
B24: 注：检验日期为终检日期，由施工单位负责填写。

Sheet 田块平整报验表
G2: 田块平整 | T2: 单元工程施工质量报验单
B4: ( | O4: 承包 | Q4: [ | U4: ] 质报 | Z4: 号)
B5: 合同名称： | H5: 布拖县2024年高标准农田建设项目（增发国债） | Y5: 合同编号：
B7: 致（监理机构）： | H7: 中浩宇项目管理有限公司
E8: =土方开挖评定表!L7 -> 2024HD10地块-@file_num田块 | M8: =G2 -> 田块平整 | P8: □ | Q8: 工序/ | S8:  | T8: 单元工程已按合同要求完成施工，经自检合格，报请贵
C9: 方复核。
E10: 附： | G10: □ | X10: 工序施工质量评定表 | AM10: 0
G11: □ | X11: 工序施工质量检查、检测记录 | AM11: 0
G12: □ | I12: 田块平整 | X12: 单元工程施工质量评定表 | AM12: 1
G13: □ | X13: 单元工程施工质量检查、检测记录 | AM13: 0
P18: 承包人：（现场机构名称及盖章）
P19: 质检负责人：（签名）
P20: 日 期： | T20: 年 月 日
B21: 监理机构 意 见 | F21: 复核结果：
G23: □ | H23: 同意进入下一工序 | U23: □ | W23: 不同意进入下一工序
G24: □ | H24: 同意进入下一单元工程 | U24: □ | W24: 不同意进入下一单元工程
F26: 附件：监理复核支持材料。
P28: 监理机构：（名称及盖章）
P29: 监理工程师：（签名）
P30: 日 期： | T30: 年 月 日
B31: 说明：本表一式 | J31: 份，由承包人填写。监理机构复核后，监理机构 | AA31: 份，返承包人 | AH31: 份。

Sheet 田块平整质量评定表
B2: 田块平整单元工程质量检验评定表
B3: 项目名称： | F3: 布拖县2024年高标准农田建设项目（增发国债） | Z3: 合同编号：
B4: 单位（子单位）工程名称或编码 | M4: =表土玻璃和回覆质量评定表!M4 -> 土地平整工程 | W4: 工程量
B5: 分部工程名称或编码 | M5: =表土玻璃和回覆质量评定表!M5 -> 2024HD10地块土地平整 | W5: 检验日期 | AA5: 年 月 日
B6: 单元工程名称 | M6: =表土玻璃和回覆质量评定表!M6 -> 2024HD10地块-@file_num田块 | W6: 田块平整
B7: 项次 | D7: 检查项目 | M7: 质量标准 | AA7: 检验结果
B8: 1 | D8: 田块形状、面积大小 | M8: 田块形状、面积大小应符合设计要求 | AA8: 符合要求
B9: 项次 | D9: 检测项目 | M9: 允许偏差 | Q9: 检测值 | AA9: 合格率 （%）
B10: 1 | D10: 田面高程 | M10: ±50mm | Q10: @int<-50,50>.cell | R10: @int<-50,50>.cell | S10: @int<-50,50>.cell | T10: @int<-50,50>.cell | U10: @int<-50,50>.cell | V10: @int<-50,50>.cell | W10: @int<-50,50>.cell | X10: @int<-50,50>.cell | Y10: @int<-50,50>.cell | Z10: @int<-50,50>.cell | AA10: =(COUNTIF(Q10:Z10,">=-50")-COUNTIF(Q10:Z10,">50"))/COUNT(Q10:Z10) -> #DIV/0!
B11: 2 | D11: 田面坡度 | M11: 符合设计要求 | Q11: @int<3,8>.cell | R11: @int<3,8>.cell | S11: @int<3,8>.cell | T11: @int<3,8>.cell | U11: @int<3,8>.cell | V11: @int<3,8>.cell | W11: @int<3,8>.cell | X11: @int<3,8>.cell | Y11: @int<3,8>.cell | Z11: @int<3,8>.cell | AA11: =(COUNTIF(Q11:Z11,">=3")-COUNTIF(Q11:Z11,">8"))/COUNT(Q11:Z11) -> #DIV/0!
B12: 共检测 | E12: 20 | G12: 点，其中合格 | K12: =SUM(AA10:AH11)*10 -> #DIV/0! | M12: 点，合格率 | Q12: =AVERAGE(AA10:AH11)*100 -> #DIV/0! | S12: %
B14: 评定结论：
H15: □ | I15: 合格 | M15: □ | N15: 不合格
B16: 施工单位（盖章） | R16: 监理单位（盖章）
B17: 质检员： | R17: 监理工程师：
B18: 质量（技术）负责人：
J19: 年 月 日 | Z19: 年 月 日
B20: 注：检验日期为终检日期，由施工单位负责填写。

Sheet 混凝土预制构件安装单元
A1: 布拖2024年高标准农田建设项目（增发国债）工程
A2: 表2.8 混凝土预制构件安装单元工程施工质量验收评定表
A3: 单位工程名称 | D3: 进水闸工程 | F3: 单元工程量 | G3: 9m³
A4: 分部工程名称 | D4: 交通桥 | F4: 施工单位 | G4: 四川华浩建筑工程有限公司
A5: 单元工程名称、部位 | D5: 第2跨预制梁安装 | F5: 施工日期 | G5: 年 月 日～ 年 月 日
A6: 项次 | B6: 工序编号 | E6: 工序质量验收评定等级
A7: 1 | B7: 构件外观质量检查 | E7: 合格
A8: 2 | B8: △预制件吊装工序 | E8: 合格
A9: 3 | B9: 预制件接缝及接头处理 | E9: 合格
A10: 施工 单位 自评 意见 | C10: 各工序施工质量全部合格，其中优良工序占_0__%，且主要工序达到____合格____等级，各项报验资料____符合____SL 632—2012 的要求。
C12: 单元工程质量等级评定为：合格
C20: （签字，加盖公章）
C21: 年 月 日
A22: 监理 单位 复核 意见 | C22: 经抽查并查验相关检验报告和检验资料，各工序施工质量全部合格，其中优良工序占__/__%，且主要工序达到_______等级，各项报验资料_____SL 632—2012的要求。
C25: 单元工程质量等级评定为：
C31: （签字，加盖公章）
C32: 年 月 日
A33: 注：本表所填“单元工程量”不作为施工单位工程量结算计量的依据。

Sheet 混凝土构件外观质量检查工序
A1: 布拖2024年高标准农田建设项目（增发国债）工程
A2: 表2.8.1 混凝土构件外观质量检查工序施工质量验收评定表
A3: 单位工程名称 | D3: 进水闸工程 | F3: 工序编号 | G3: /
A4: 分部工程名称 | D4: 交通桥 | F4: 施工单位 | G4: 四川华浩建筑工程有限公司
A5: 单元工程名称、部位 | D5: 第2跨预制梁安装 | F5: 施工日期 | G5: 年 月 日～ 年 月 日
A6: 项次 | C6: 检验项目 | E6: 质量要求 | H6: 检查记录 | I6: 合格数 | J6: 合格率
A7: 主控项目 | B7: 1 | C7: 外观检查 | E7: 无缺陷 | H7: 外观无缺陷，检查结果完全符合质量要求。 | I7: / | J7: 1
B10: 2 | C10: 尺寸偏差 | E10: 预制构件不应有影响结构性能和安装、使用功能的尺寸偏差 | H10: 无影响结构性能的安装、使用功能的尺寸偏差，结构尺寸完全符合质量要求。 | I10: / | J10: 1
A11: 一般项目 | B11: 1 | C11: 预制构件标识 | E11: 应在明显部位标明生产单位、构件型号、生产日期和质量验收标志 | H11: 现场浇制T型梁，标有生产日期和验收日期和安装位置编号，检查结果基本符合质量要求。 | I11: / | J11: 0.7
B13: 2 | C13: 构件上的预埋件、插筋和预留孔洞的规格、位置和数量 | E13: 应符合标准图或设计的要求 | H13: 构件上的预埋件、连接钢筋预留孔洞等的规格、数量、位置均基本符合质量要求。 | I13: / | J13: 0.7
A14: 施工 单位 自评 意见 | C14: 主控项目检验点全部合格，一般项目逐项检验点的合格率均不小于___70__%，且不合格点不集中分布，各项报验资料___符合__SL 632—2012的要求。
C16: 工序质量等级评定为：合格
C22: （签字，加盖公章）
C23: 年 月 日
A24: 监理 单位 复核 意见 | C24: 经复核，主控项目检验点全部合格，一般项目逐项检验点的合格率均不小于_____%，且不合格点不集中分布，各项报验资料_____SL 632—2012的要求。
C26: 工序质量等级评定为：
C32: （签字，加盖公章）
C33: 年 月 日

Sheet 预制件吊装工序
A1: 布拖2024年高标准农田建设项目（增发国债）工程
A2: 表2.8.2 预制件吊装工序施工质量验收评定表（未找到对应设计值）
A3: 单位工程名称 | F3: 进水闸工程 | H3: 工序编号 | I3: /
A4: 分部工程名称 | F4: 交通桥 | H4: 施工单位 | I4: 四川华浩建筑工程有限公司
A5: 单元工程名称、部位 | F5: 第2跨预制梁安装 | H5: 施工日期 | I5: 年 月 日～ 年 月 日
A6: 项次 | C6: 检验项目 | G6: 质量要求 | I6: 检查记录 | O6: 合格数 | P6: 合格率
A7: 主控项目 | B7: 1 | C7: 构件型号和安装位置 | G7: 符合设计要求 | I7: T型梁浇制符合质量要求，安装位置符合梁上标明的安装位置编号，检查结果完全符合质量要求。 | O7: / | P7: 1
B8: 2 | C8: 构件吊装时的混凝土强度 | G8: 符合设计要求。设计无规定时，不应低于设计强度标准值的70%；预应力构件孔道灌浆的强度，应达到设计要求 | I8: 吊装时已养护28天并已做抗压强度试验，抗压强度34.7MPa，检查结果完全符合质量要求。 | O8: / | P8: 1
G9: 设计强度C30
A10: 一般项目 | B10: 1 | C10: 柱 | D10: 中心线和轴线位移 | G10: 允许偏差±5mm | I10: / | O10: / | P10: /
B11: 2 | D11: 垂直度 | E11: 柱高10m以下 | G11: 允许偏差10mm | I11: / | O11: / | P11: /
B12: 3 | E12: 柱高10m及其以上 | G12: 允许偏差20mm | I12: / | O12: / | P12: /
B13: 4 | D13: 牛腿上表面、柱顶标高 | G13: 允许偏差-8～Omm | I13: / | O13: / | P13: /
B14: 5 | C14: 梁或吊车梁 | D14: 中心线和轴线位移 | G14: 允许偏差±5mm | I14: @int<-5,5>，@int<-5,5>，@int<-5,5>，@int<-5,5>，@int<-5,5>，@int<-5,5>，@int<-5,5>，@int<-5,5>，@int<-5,5>，@int<-5,5> | O14: 8 | P14: 80
B15: 6 | D15: 梁顶面标高 | G15: 允许偏差-5～Omm | I15: 设计值279.5m，实测值（m）：@float.3<279.495,279.5>，@float.3<279.495,279.5>，@float.3<279.495,279.5>，@float.3<279.495,279.5>，@float.3<279.495,279.5>，@float.3<279.495,279.5>，@float.3<279.495,279.5>，@float.3<279.495,279.5>，@float.3<279.495,279.5>，@float.3<279.495,279.5> | O15: 8 | P15: 80
B16: 7 | C16: 屋面 | D16: 下弦中心线和轴线位移 | G16: 允许偏差±5mm | I16: / | O16: / | P16: /
B17: 8 | D17: 垂直 | E17: 桁架、拱形屋架 | G17: 允许偏差1/250屋架高 | I17: / | O17: / | P17: /
B18: 9 | D18: 度 | E18: 薄膜梁 | G18: 允许偏差5mm | I18: / | O18: / | P18: /
B19: 10 | C19: 板 | D19: 相邻两板下表面平整 | E19: 抹灰 | G19: 允许偏差5mm | I19: / | O19: / | P19: /
B20: 11 | E20: 不抹灰 | G20: 允许偏差3mm | I20: / | O20: / | P20: /
B21: 12 | C21: 预制廊道、井筒板（埋入建筑物） | E21: 中心线和轴线位移 | G21: 允许偏差±20mm | I21: @int<1,4>，@int<1,4>，@int<1,4>，@int<1,4>，@int<1,4>，@int<1,4>，@int<1,4> | O21: 6 | P21: 0.857
B23: 13 | E23: 相邻两构件的表面平整 | G23: 允许偏差10mm | I23: 设计值2.5m，实测值：@float.3<2.49,2.51>，@float.3<2.49,2.51>，@float.3<2.49,2.51>，@float.3<2.49,2.51>，@float.3<2.49,2.51>，@float.3<2.49,2.51>，@float.3<2.49,2.51>，@float.3<2.49,2.51>，@float.3<2.49,2.51>，@float.3<2.49,2.51> | O23: 8 | P23: 0.8
B25: 14 | C25: 建筑物外表面模板 | E25: 相邻两板面高差 | G25: 允许偏差3mm（局部5mm） | I25: / | O25: / | P25: /
E26: 外边线与结构物边线 | G26: 允许偏差±10mm | I26: / | O26: / | P26: /
A27: 施工 单位 自评 意见 | C27: 主控项目检验点全部合格，一般项目逐项检验点的合格率均不小于___70__%，且不合格点不集中分布，各项报验资料___符合__SL 632—2012的要求。
C28: 工序质量等级评定为：合格
C30: （签字，加盖公章）
C31: 年 月 日
A32: 监理 单位 复核 意见 | C32: 经复核，主控项目检验点全部合格，一般项目逐项检验点的合格率均不小于_____%，且不合格点不集中分布，各项报验资料_____SL 632—2012的要求。
C33: 工序质量等级评定为：
C35: （签字，加盖公章）
C36: 年 月 日

Sheet 预制件接缝及接头处理工序
A1: 布拖2024年高标准农田建设项目（增发国债）工程
A2: 表2.8.3 预制件接缝及接头处理工序施工质量验收评定表
A3: 单位工程名称 | D3: 进水闸工程 | F3: 工序编号 | G3: /
A4: 分部工程名称 | D4: 交通桥 | F4: 施工单位 | G4: 四川华浩建筑工程有限公司
A5: 单元工程名称、部位 | D5: 第2跨预制梁安装 | F5: 施工日期 | G5: 年 月 日～ 年 月 日
A6: 项次 | C6: 检验项目 | E6: 质量要求 | H6: 检查记录 | I6: 合格数 | J6: 合格率
A7: 主控项目 | B7: 1 | C7: 构件连接 | E7: 构件与底座、构件与构件的连接应符合设计要求，受力接头应符合GB 50204的规定 | H7: 构件底部和底座平整，构件与底座、构件间预留钢筋现浇C30混凝土连接，检查结果完全符合质量要求。 | I7: / | J7: 1
A8: 一般项目 | B8: 1 | C8: 接缝凿毛处理 | E8: 符合设计要求 | H8: 接缝凿成毛面，清除浮渣，冲洗干净，检查结果基本符合质量要求。 | I8: / | J8: 0.7
B9: 2 | C9: 构件接缝的混凝土（砂浆） | E9: 养护符合设计要求，且在规定的时间内不应拆除其支承模板 | H9: 设计养护龄期为28天标准养护，14天才可拆模，混凝土初凝后开始洒水养护，保持表面湿润，验收评定后继续养护到28天，第15天进行拆模工作，检查结果基本符合质量要求。 | I9: / | J9: 0.7
A10: 施工 单位 自评 意见 | C10: 主控项目检验点全部合格，一般项目逐项检验点的合格率均不小于__70___%，且不合格点不集中分布，各项报验资料___符合__SL 632—2012的要求。
C12: 工序质量等级评定为：合格
C19: （签字，加盖公章）
C20: 年 月 日
A21: 监理 单位 复核 意见 | C21: 经复核，主控项目检验点全部合格，一般项目逐项检验点的合格率均不小于_____%，且不合格点不集中分布，各项报验资料_____SL 632—2012的要求。
C23: 工序质量等级评定为：
C30: （签字，加盖公章）
C31: 年 月 日

Sheet 普通混凝土单元
A1: 布拖2024年高标准农田建设项目（增发国债）工程
A2: 表2.1 普通混凝土单元工程施工质量验收评定表
A3: 单位工程名称 | D3: 进水闸工程 | F3: 单元工程量 | G3: 1020
A4: 分部工程名称 | D4: 闸室段 | F4: 施工单位 | G4: 四川华浩建筑工程有限公司
A5: 单元工程名称、部位 | D5: 2#闸墩，▽152.500～154.500m | F5: 施工日期 | G5: 年 月 日～ 年 月 日
A6: 项次 | B6: 工序编号 | E6: 工序质量验收评定等级
A7: 1 | B7: 基础面 | E7: 合格
B8: 施工缝处理工序 | E8: 合格
A9: 2 | B9: 模板制作及安装工序 | E9: 合格
A10: 3 | B10: △钢筋制作及安装工序 | E10: 合格
A11: 4 | B11: 预埋件（止水、伸缩缝等）制作及安装 | E11: 合格
A12: 5 | B12: △混凝土浇筑工序 | E12: 合格
A13: 6 | B13: 混凝土外观质量检查工序 | E13: 合格
A14: 施工 单位 自评 意见 | C14: 各工序施工质量全部合格，其中优良工序占__0__%，且主要工序达到____合格____等级，单元工程试块质量
C15: 检验合格，各项报验资料____符合____SL 632—2012 的要求。
C16: 单元工程质量等级评定为： | E16: 合格
C22: （签字，加盖公章）
C23: 年 月 日
A24: 监理 单位 复核 意见 | C24: 经抽查并查验相关检验报告和检验资料，各工序施工质量全部合格，其中优良工序占____%，且
C25: 主要工序达到_______等级，单元工程试块质量检验合格，各项报验资料_____SL 632—2012的要求。
C26: 单元工程质量等级评定为：
C32: （签字，加盖公章）
C33: 年 月 日
A34: 注：本表所填“单元工程量”不作为施工单位工程量结算计量的依据。

Sheet 基础面处理工序
A1: 布拖2024年高标准农田建设项目（增发国债）工程
A2: 表2.1.1-1 基础面处理工序施工质量验收评定表
A3: 单位工程名称 | E3: =[1]普通混凝土单元!D3 -> 进水闸工程 | H3: 工序编号
A4: 分部工程名称 | E4: =[1]普通混凝土单元!D4 -> 闸室段 | H4: 施工单位 | J4: 四川华浩建筑工程有限公司
A5: 单元工程名称、部位 | E5: =[1]普通混凝土单元!D5 -> 2#闸墩，▽152.500～154.500m | H5: 施工日期 | J5: 年 月 日～ 年 月 日
A6: 项次 | C6: 检验项目 | G6: 质量要求 | I6: 检查记录 | K6: 合格数 | L6: 合格率
A7: 基础面 | B7: 主控项目 | C7: 1 | D7: 基础面 | F7: 山基石 | G7: 符合设计要求 | I7: 没有松动岩块、浮渣，检查结果完全符合质量要求。 | K7: / | L7: 1
F8: 软基 | G8: 预留保护层已挖除；基础面符合设计要求 | I8: / | K8: / | L8: /
C9: 2 | D9: 地表水和地下水 | G9: 妥善引排或封堵 | I9: 已进行妥善引排，检查结果完全符合质量要求。 | K9: / | L9: 1
B10: 一般项目 | C10: 1 | D10: 岩面清理 | G10: 符合设计要求；清洗洁净、无积水、无积渣杂物 | I10: 清洗洁净，无积渣、无杂物，无积水，检查结果基本符合质量要求。 | K10: / | L10: 0.7
A11: 施工 单位 自评 意见 | C11: 主控项目检验点全部合格，一般项目逐项检验点的合格率均不小于__70___%，且不合格点不集中分布，
C12: 各项报验资料__符合___SL 632—2012的要求。
C13: 工序质量等级评定为：
C16: （签字，加盖公章）
C17: 年 月 日
A18: 监理 单位 复核 意见 | C18: 经复核，主控项目检验点全部合格，一般项目逐项检验点的合格率均不小于_____%，且不合格点
C19: 不集中分布，各项报验资料_____SL 632—2012的要求。
C20: 工序质量等级评定为：
C23: （签字，加盖公章）
C24: 年 月 日

Sheet 施工缝处理工序
A1: 布拖2024年高标准农田建设项目（增发国债）工程
A2: 表2.1.1-2 普通混凝土施工缝处理工序施工质量验收评定表（未找到对应设计值）
A4: 单位工程名称 | E4: =[1]普通混凝土单元!D3 -> 进水闸工程 | H4: 工序编号 | I4: /
A5: 分部工程名称 | E5: =[1]普通混凝土单元!D4 -> 闸室段 | H5: 施工单位 | I5: 四川华浩建筑工程有限公司
A6: 单元工程名称、部位 | E6: =[1]普通混凝土单元!D5 -> 2#闸墩，▽152.500～154.500m | H6: 施工日期 | I6: 年 月 日-- 年 月 日
A7: 项次 | B7: 检验项目 | F7: 质量要求 | G7: 检查记录 | J7: 合格数 | K7: 合格率
A8: 主控项目 | B8: 1 | D8: 施工缝的留置位置 | F8: 符合设计或有关施工规范规定 | G8: 施工缝留设在0+120位置，检查结果完全符合质量要求。 | J8: / | K8: 1
B9: 2 | D9: 施工缝面凿毛 | F9: 基面无乳皮，成毛面，微露粗砂 | G9: 已按要求凿成毛面，无乳皮，微漏粗砂，检查结果完全符合质量要求。 | J9: / | K9: 1
A10: 一般项目 | B10: 1 | D10: 缝面清理 | F10: 符合设计要求；清洗洁净、无积水、无积渣杂物 | G10: 清洁洁净，无积水，无积渣、杂物，检查结果基本符合质量要求。 | J10: / | K10: 0.7
A11: 施工 单位 自评 意见 | C11: 主控项目检验点全部合格，一般项目逐项检验点的合格率均不小于__70___%，且不合格点不集中分布，
C12: 各项报验资料__符合___SL 632—2012的要求。
C13: 工序质量等级评定为：_____合格_____。
C17: （签字，加盖公章） 年 月 日
A18: 监理 单位 复核 意见 | C18: 经复核，主控项目检验点全部合格，一般项目逐项检验点的合格率均不小于_____%，且不合格点
C19: 不集中分布，各项报验资料_____SL 632—2012的要求。
C20: 工序质量等级评定为：__________。
C24: （签字，加盖公章） 年 月 日

Sheet 模板制作及安装工序
A1: 布拖2024年高标准农田建设项目（增发国债）工程
A2: 表2.1.2 模板制作及安装工序施工质量验收评定表（未找到对应设计值）
A3: 单位工程名称 | D3: =[1]普通混凝土单元!D3 -> 进水闸工程 | H3: 工序编号 | J3: /
A4: 分部工程名称 | D4: =[1]普通混凝土单元!D4 -> 闸室段 | H4: 施工单位 | J4: 四川华浩建筑工程有限公司
A5: 单元工程名称、部位 | D5: =[1]普通混凝土单元!D5 -> 2#闸墩，▽152.500～154.500m | H5: 施工日期 | J5: 年 月 日～ 年 月 日
A6: 项次 | C6: 检验项目 | F6: 质量要求 | I6: 检查记录 | O6: 合格数 | P6: 合格率
A7: 主控项目 | B7: 1 | C7: 稳定性、刚度和强度 | F7: 满足混凝土施工荷载要求，并符合模板设计要求 | I7: 钢支撑加拉筋固定，稳定性、刚度和强度检查结果完全符合质量要求。 | O7: / | P7: 1
B8: 2 | C8: 承重模板底面高程 | F8: 允许偏差0～+5mm | I8: / | O8: / | P8: /
B9: 3 | C9: 排架、梁板、柱、墙 | E9: 结构断面尺寸 | F9: 允许偏差±10mm | I9: @int<-10,10>，@int<-10,10>，@int<-10,10>，@int<-10,10>，@int<-10,10>，@int<-10,10>，@int<-10,10>，@int<-10,10>，@int<-10,10>，@int<-10,10>，@int<-10,10>，@int<-10,10>，@int<-10,10>，@int<-10,10>，@int<-10,10>，@int<-10,10>，@int<-10,10>，@int<-10,10>，@int<-10,10>，@int<-10,10> | O9: 20 | P9: 1
E11: 轴线位置 | F11: 允许偏差±10mm | I11: @int<-10,10>，@int<-10,10>，@int<-10,10>，@int<-10,10>，@int<-10,10>，@int<-10,10>，@int<-10,10>，@int<-10,10>，@int<-10,10>，@int<-10,10>，@int<-10,10>，@int<-10,10>，@int<-10,10>，@int<-10,10>，@int<-10,10>，@int<-10,10>，@int<-10,10>，@int<-10,10>，@int<-10,10>，@int<-10,10> | O11: 20 | P11: 1
E13: 垂直度 | F13: 允许偏差±5mm | I13: 清洁洁净，无积水，无积渣、杂物，检查结果基本符合质量要求。 | O13: 20 | P13: 1
B15: 4 | C15: 结构物边线与设计边线 | E15: 外露表面 | F15: 内模板允许偏差0～+10m，外模板允许偏差-10mm～0 | I15: 设计值：8.5×15m，内模板：@float.3<8.495,8.5>，@float.3<8.495,8.5>，@float.3<8.495,8.5>，@float.3<8.495,8.5>，@float.3<8.495,8.5>，@float.3<8.495,8.5>，@float.3<8.495,8.5>，@float.3<8.495,8.5>，@float.3<8.495,8.5>，@float.3<8.495,8.5>；外模板：@float.3<15,15.01>，@float.3<15,15.01>，@float.3<15,15.01>，@float.3<15,15.01>，@float.3<15,15.01>，@float.3<15,15.01>，@float.3<15,15.01>，@float.3<15,15.01>，@float.3<15,15.01>，@float.3<15,15.01> | O15: 20 | P15: 1
E17: 隐蔽内面 | F17: 允许偏差15mm | I17: / | O17: / | P17: /
B19: 5 | C19: 预留孔、洞尺寸及位置 | E19: 孔、洞尺寸 | F19: 允许偏差0 - +10mm | I19: 设计值：1.0m×1.2m，实测值： @float.3<1.0,1.01>×@float.3<1.2,1.21>， @float.3<1.0,1.01>×@float.3<1.2,1.21>，@float.3<1.0,1.01>×@float.3<1.2,1.21>，@float.3<1.0,1.01>×@float.3<1.2,1.21> | O19: 4 | P19: 1
E20: 孔洞位置 | F20: 允许偏差±10mm | I20: 设计（m）坝纵：0+61.7，坝横：0+11.3；实测（m）坝纵：0+@float.3<61.7,61.71>，坝横：0+@float.3<11.3,11.31> | O20: 2 | P20: 1
A21: 一般项目 | B21: 1 | C21: 模板平整度、相邻两板面错台 | E21: 外露表面 | F21: 钢模：允许偏差2mm 木模：允许偏差3mm | I21: @float.3<0.2,1.7>，@float.3<0.2,1.7>，@float.3<0.2,1.7>，@float.3<0.2,1.7>，@float.3<0.2,1.7>，@float.3<0.2,1.7>，@float.3<0.2,1.7>，@float.3<0.2,1.7>，@float.3<0.2,1.7>，@float.3<0.2,1.7>，@float.3<0.2,1.7>，@float.3<0.2,1.7>，@float.3<0.2,1.7>，@float.3<0.2,1.7>，@float.3<0.2,1.7>，@float.3<0.2,1.7>，@float.3<0.2,1.7>，@float.3<0.2,1.7>，@float.3<0.2,1.7>，@float.3<0.2,1.7> | O21: 20 | P21: 1
E23: 隐蔽内面 | F23: 允许偏差5mm | I23: / | O23: / | P23: /
B24: 2 | C24: 局部平整度 | E24: 外露表面 | F24: 钢模：允许偏差3mm 木模：允许偏差5mm | I24: @float.3<0.8,3.1>，@float.3<0.8,3.1>，@float.3<0.8,3.1>，@float.3<0.8,3.1>，@float.3<0.8,3.1>，@float.3<0.8,3.1>，@float.3<0.8,3.1>，@float.3<0.8,3.1>，@float.3<0.8,3.1>，@float.3<0.8,3.1>，@float.3<0.8,3.1>，@float.3<0.8,3.1>，@float.3<0.8,3.1>，@float.3<0.8,3.1>，@float.3<0.8,3.1>，@float.3<0.8,3.1>，@float.3<0.8,3.1>，@float.3<0.8,3.1>，@float.3<0.8,3.1>，@float.3<0.8,3.1>，@float.3<0.8,3.1>，@float.3<0.8,3.1>，@float.3<0.8,3.1>，@float.3<0.8,3.1>，@float.3<0.8,3.1>，@float.3<0.8,3.1>，@float.3<0.8,3.1>，@float.3<0.8,3.1>，@float.3<0.8,3.1>，@float.3<0.8,3.1> | O24: 26 | P24: 0.867
E26: 隐蔽内面 | F26: 允许偏差10mm | I26: / | O26: / | P26: /
B27: 3 | C27: 板面缝隙 | E27: 外露表面 | F27: 钢模：允许偏差1mm 木模：允许偏差2mm | I27: @float.3<0.2,1.1>，@float.3<0.2,1.1>，@float.3<0.2,1.1>，@float.3<0.2,1.1>，@float.3<0.2,1.1>，@float.3<0.2,1.1>，@float.3<0.2,1.1>，@float.3<0.2,1.1>，@float.3<0.2,1.1>，@float.3<0.2,1.1> | O27: 8 | P27: 0.8
E29: 隐蔽内面 | F29: 允许偏差2mm | I29: / | O29: / | P29: /
B30: 4 | C30: 结构物水平断面内部尺寸 | F30: 允许偏差±20mm | I30: 设计值：17×30m，实测值： @float.3<16.98,17.02>×@float.3<29.98,30.02>，@float.3<16.98,17.02>×@float.3<29.98,30.02>，@float.3<16.98,17.02>×@float.3<29.98,30.02>，@float.3<16.98,17.02>×@float.3<29.98,30.02>，@float.3<16.98,17.02>×@float.3<29.98,30.02>，@float.3<16.98,17.02>×@float.3<29.98,30.02>，@float.3<16.98,17.02>×@float.3<29.98,30.02>，@float.3<16.98,17.02>×@float.3<29.98,30.02>，@float.3<16.98,17.02>×@float.3<29.98,30.02>，@float.3<16.98,17.02>×@float.3<29.98,30.02> | O30: 8 | P30: 0.8
B32: 5 | C32: 脱模剂涂刷 | F32: 产品质量符合标准要求，涂刷均匀，无明显色差 | I32: 脱模剂符合质量标准，涂刷均匀，无漏涂，无明显色差，经检查结果基本符合质量要求。 | O32: / | P32: 0.7
B33: 6 | C33: 模板外观 | F33: 表面光洁、无污物 | I33: 表面光洁，个别点有污物已清除，经检查结果基本符合质量要求。 | O33: / | P33: 0.7
A34: 施工 单位 自评 意见 | C34: 主控项目检验点全部合格，一般项目逐项检验点的合格率均不小于___70__%，且不合格点不集中分布，各项报验资料___符合__SL 632—2012的要求。
C36: 工序质量等级评定为： | F36: 合格
C38: （签字，加盖公章）
C39: 年 月 日
A40: 监理 单位 复核 意见 | C40: 经复核，主控项目检验点全部合格，一般项目逐项检验点的合格率均不小于_____%，且不合格点不集中分布，各项报验资料_____SL 632—2012的要求。
C42: 工序质量等级评定为：
C45: （签字，加盖公章）
C46: 年 月 日

Sheet 钢筋制作及安装工序
A1: 布拖2024年高标准农田建设项目（增发国债）工程
A2: 表2.1.3 钢筋制作及安装工序施工质量验收评定表（未找到对应设计值）
A3: 单位工程名称 | E3: =[1]普通混凝土单元!D3 -> 进水闸工程 | H3: 工序编号 | I3: /
A4: 分部工程名称 | E4: =[1]普通混凝土单元!D4 -> 闸室段 | H4: 施工单位 | I4: =[1]普通混凝土单元!G4 -> 四川华浩建筑工程有限公司
A5: 单元工程名称、部位 | E5: =[1]普通混凝土单元!D5 -> 2#闸墩，▽152.500～154.500m | H5: 施工日期 | I5: 年 月 日～ 年 月 日
A6: 项次 | C6: 检验项目 | G6: 质量要求 | I6: 检查记录 | O6: 合格数 | P6: 合格率
A7: 主控项目 | B7: 1 | C7: 钢筋的数量、规格尺寸、安装位置 | G7: 符合质量标准和设计的要求 | I7: 钢筋的数量、规格尺寸、安装位置符合要求 | O7: / | P7: 1
B8: 2 | C8: 钢筋接头的力学性能 | G8: 符合规范要求和国家及行业有关规定 | I8: 采用直螺纹连接，抽2组检验，附检测试验报告。 | O8: 2 | P8: 1
B9: 3 | C9: 焊接接头和焊缝外观 | G9: 不允许有裂缝、脱焊点、漏焊点，表面平顺，没有明显的咬边、凹陷、气孔等，钢筋不应有明显烧伤 | I9: / | O9: / | P9: /
B10: 4.钢筋连接 | C10: 点焊及电弧焊 | D10: 帮条对焊接头中心 | G10: 纵向偏移差不大于0.5d | I10: / | O10: / | P10: /
D11: 接头处钢筋轴线的曲折 | G11: ≤4° | I11: / | O11: / | P11: /
D12: 焊缝 | F12: 长度 | G12: 允许偏差－0.5d | I12: / | O12: / | P12: /
F13: 高度 | G13: 允许偏差－0.05d | I13: / | O13: / | P13: /
F14: 表面气孔夹渣 | G14: 在2d长度上数量不多于2个；气孔、夹渣的直径不大于3mm | I14: / | O14: / | P14: /
C15: 对焊及溶槽焊 | D15: 焊接接头根部未焊透深度 | F15: Φ25～Φ4Omm钢筋 | G15: ≤0.15d | I15: / | O15: / | P15: /
F16: Φ40～ | G16: ≤0.10d | I16: / | O16: / | P16: /
F17: Φ70mm钢筋
D18: 接头处钢筋中心线的位移 | G18: 0.10d且不大于2mm | I18: / | O18: / | P18: /
D19: 焊缝表面（长为2d）和焊缝截面上蜂窝、气孔、非金属杂质 | G19: ≤1.5d | I19: / | O19: / | P19: /
C20: 绑扎连接 | D20: 缺扣、松扣 | G20: ≤20%，且不集中 | I20: 全面检查后，抽检10处，每处10扣，7处无缺扣松扣，3处各有1个松扣。 | O20: / | P20: 1
D21: 弯钩朝向正确 | G21: 符合设计图纸 | I21: 弯钩朝向符合图纸要求。 | O21: / | P21: 1
D22: 搭接长度 | G22: 允许偏差－0.05设计值 | H22: 660mm | I22: 实测值（mm）：@float.2<659.95,660>，@float.2<659.95,660>，@float.2<659.95,660>，@float.2<659.95,660>，@float.2<659.95,660>，@float.2<659.95,660>，@float.2<659.95,660>，@float.2<659.95,660>，@float.2<659.95,660>，@float.2<659.95,660> | O22: 10 | P22: 1
A24: 续表2.1.3
A25: 项次 | C25: 检验项目 | G25: 质量标准 | I25: 检查（测）记录 | O25: 合格数 | P25: 合格率
A26: 主控项目 | B26: 4.钢筋连接 | C26: 机械连接 | D26: 带肋钢筋冷挤压连接接头 | E26: 压痕处套筒外形尺寸 | G26: 挤压后套筒长度应为原套筒长度的1.10～1.15倍，或压痕处套筒的外径波动范围为原套筒外径的0.8～0.9倍 | I26: / | O26: / | P26: /
E27: 挤压道次 | G27: 符合型式检验结果 | I27: / | O27: / | P27: /
E28: 接头弯折 | G28: ≤4° | I28: / | O28: / | P28: /
E29: 裂缝检查 | G29: 挤压后肉眼观察无裂缝 | I29: / | O29: / | P29: /
D30: 直锥由螺纹连接接头 | E30: 丝头外观质量 | G30: 保护良好，无锈蚀和油污，牙形饱满光滑 | I30: 丝头上保护剂，并套上保护套妥善保护，无锈蚀和油污，牙形完整光滑，检查结果完全符合质量要求。 | O30: / | P30: 1
E31: 套头外观质量 | G31: 无裂纹或其他肉眼可见缺陷 | I31: 套筒无裂缝，完好无损无缺陷，检查结果完全符合质量要求。 | O31: / | P31: 1
E32: 外露丝扣 | G32: 无1扣以上完整丝扣外露 | I32: 经检查，无1扣以上完整丝扣外露现象，检查结果完全符合质量要求。 | O32: / | P32: 1
E33: 螺纹匹配 | G33: 丝头螺纹与套筒螺纹满足连接要求，螺纹结合紧密，无明显松动，以及相应处理方法得当 | I33: 丝头与套筒螺纹匹配，螺纹结合紧密，用力矩扳手扭紧，检查无松动，检查结果完全符合质量要求。 | O33: / | P33: 1
B34: 5.钢筋间距、保护层 | G34: 符合规范和设计要求 | I34: 全面检查，无明显过大过小现象，检查结果完全符合质量要求。 | O34: / | P34: 1
B35: 6.保护层厚度 | G35: 允许偏差±1/4净保护层厚 | H35: 设计值：50mm | I35: 实测值：@int<40,60>，@int<40,60>，@int<40,60>，@int<40,60>，@int<40,60>，@int<40,60>，@int<40,60>，@int<40,60>，@int<40,60>，@int<40,60> | O35: 10 | P35: 1
A36: 一般项目 | B36: 1 | C36: 钢筋长度方向 | G36: 局部偏差±1/2净保护层厚 | H36: 设计值：29.9m，16.9m | I36: 实测值：@float.3<29.88,29.915>，@float.3<29.88,29.915>，@float.3<29.88,29.915>，@float.3<29.88,29.915>，@float.3<29.88,29.915> ，@float.3<16.875,16.901>，@float.3<16.875,16.901>，@float.3<16.875,16.901>，@float.3<16.875,16.901>，@float.3<16.875,16.901> | O36: 9 | P36: 0.9
B38: 2 | C38: 同一排受力钢筋间距 | F38: 排架、梁、柱 | G38: 允许偏差±0.5d | I38: / | O38: / | P38: /
F40: 板、墙 | G40: 允许偏差±0.1倍间距 | H40: 设计150mm，200mm | I40: 实测值：@int<145,155>，@int<145,155>，@int<145,155>，@int<145,155>，@int<145,155>，@int<145,155>，@int<145,155>，@int<145,155>，@int<145,155>，@int<145,155> ，@int<180,220>，@int<180,220>，@int<180,220>，@int<180,220>，@int<180,220>，@int<180,220>，@int<180,220>，@int<180,220>，@int<180,220>，@int<180,220> | O40: 16 | P40: 0.8
B42: 3 | C42: 双排钢筋，其排与排间距（间距200mm） | G42: 允许偏差±0.1倍排距 | I42: / | O42: / | P42: /
B44: 4 | C44: 梁与柱中箍筋间距（间距200mm） | G44: 允许偏差±0.1倍箍筋间距 | I44: / | O44: / | P44: /
A46: 施工 单位 自评 意见 | C46: 主控项目检验点全部合格，一般项目逐项检验点的合格率均不小于__70___%，且不合格点不集中分布，各项报验资料__符合___SL 632—2012的要求。
...

Sheet 预埋件制作及安装工序
A1: 布拖2024年高标准农田建设项目（增发国债）工程
A2: 表2.1.4 预埋件制作及安装工序施工质量验收评定表（未找到对应设计值）
A3: 单位工程名称 | E3: =[1]普通混凝土单元!D3 -> 进水闸工程 | H3: 工序编号 | I3: /
A4: 分部工程名称 | E4: =[1]普通混凝土单元!D4 -> 闸室段 | H4: 施工单位 | I4: =[1]普通混凝土单元!G4 -> 四川华浩建筑工程有限公司
A5: 单元工程名称、部位 | E5: =[1]普通混凝土单元!D5 -> 2#闸墩，▽152.500～154.500m | H5: 施工日期 | I5: 年 月 日～ 年 月 日
A6: 项次 | D6: 检验项目 | G6: 质量要求 | J6: 检查记录 | O6: 合格数 | P6: 合格率
A7: 止水片、止水带 | B7: 主控项目 | C7: 1 | D7: 片（带）外观 | G7: 表面平整，无浮皮、锈污、油渍、砂眼、钉孔、裂纹等 | J7: 止水片表面，无各种污染和缺损，检查结果完全符合质量要求。 | O7: / | P7: 1
C8: 2 | D8: 基座 | G8: 符合设计要求（按基础面要求验收合格） | J8: 基座按设计要求处理并验收合格，无松动岩块、无浮土，检查结果完全符合质量要求。 | O8: / | P8: 1
C9: 3 | D9: 片（带）插入深度 | G9: 符合设计要求 | J9: 岸坡两块止水片插入岩基深度为：@float.2<0.59,0.62>m，@float.2<0.59,0.62>m。 | O9: 2 | P9: 1
C10: 4 | D10: 沥青井（柱） | G10: 位置准确、牢固，上下层衔接好，电热元件及绝热材料埋设准确，沥青填塞密实 | J10: / | O10: / | P10: /
C11: 5 | D11: 接头 | G11: 符合工艺要求 | J11: 止水铜片双面氧焊，焊接工艺完全符合质量要求。 | O11: / | P11: /
B12: 一般项目 | C12: 1 | D12: 片（带）偏差 | F12: 宽 | G12: 允许偏差±5mm | J12: 设计值：400mm，实测值：@int<395,405>，@int<395,405>，@int<395,405>，@int<395,405>，@int<395,405> | O12: 5 | P12: 1
F14: 高 | G14: 允许偏差±2mm | J14: 设计值：30mm，实测值：@int<28,32>，@int<28,32>，@int<28,32>，@int<28,32>，@int<28,32> | O14: 5 | P14: 1
F16: 长 | G16: 允许偏差±20mm | J16: / | O16: / | P16: /
J17: / | O17: / | P17: /
C18: 2 | D18: 搭接长度 | F18: 金属止水片 | G18: ≥20mm,双面焊接 | J18: 双面焊接，实测值：@int<20,25>，@int<20,25>，@int<20,25>，@int<20,25>，@int<20,25>，@int<20,25>，@int<20,25>，@int<20,25> | O18: 8 | P18: 1
F19: 橡胶、PVC止水带 | G19: ≥lOOmm | J19: / | O19: / | P19: /
F20: 金属止水片与PVC止水带接头栓接长度 | G20: ≥350mm（螺栓栓接法） | J20: / | O20: / | P20: /
C21: 3 | D21: 片（带）中心线与接缝中心线安装偏差 | G21: 允许偏差±5mm | J21: @int<0,5>，@int<0,5>，@int<0,5>，@int<0,5>，@int<0,5>，@int<0,5>，@int<0,5>，@int<0,5>，@int<0,5>，@int<0,5> | O21: 9 | P21: 0.9
A22: 伸缩缝（填充材料） | B22: 主控项目 | C22: 1 | D22: 伸缩缝缝面 | G22: 平整、顺直、干燥，外露铁件应割除，确保伸缩有效 | J22: 平整、顺直、干燥，无外露铁件及杂质，检查结果完全符合质量要求。 | O22: / | P22: 1
B23: 一般项目 | C23: 1 | D23: 涂敷沥青料 | G23: 涂刷均匀平整、与混凝土粘接紧密，无气泡及隆起现象 | J23: / | O23: / | P23: /
C24: 2 | D24: 粘贴沥青油毛毡 | G24: 铺设厚度均匀平整、牢固、搭接紧密 | J24: / | O24: / | P24: /
C25: 3 | D25: 铺设预制油毡板或其他闭缝板 | G25: 铺设厚度均匀平整、牢固、相邻块安装紧密平整无缝 | J25: 铺设泡沫嵌缝板厚度均匀，平整、牢固，填塞紧密无空洞，检查结果基本符合质量要求。 | O25: / | P25: 0.7
O26: 续表2.1.4
A27: 项次 | D27: 检验项目 | G27: 质量标准 | J27: 检查记录 | O27: 合格数 | P27: 合格率
A28: 排水系统 | B28: 主控项目 | C28: 1 | D28: 孔口装置 | G28: 按设计要求加工、安装，并进行防锈处理，安装牢固，不应有渗水、漏水现象 | J28: 采用PVC管，安装牢固，无渗水、漏水现象，管口用木塞堵紧，检查结果完全符合质量要求。 | O28: / | P28: 1
C29: 2 | D29: 排水管通畅性 | G29: 通畅 | J29: 经通水试验，全部通畅，检查结果完全符合质量要求。 | O29: / | P29: 1
B30: 一般项目 | C30: 1 | D30: 排水孔倾斜度 | G30: 允许偏差4% | J30: @int<1,3>，@int<1,3>，@int<1,3>，@int<1,3>，@int<1,3>，@int<1,3>，@int<1,3>，@int<1,3>，@int<1,3>，@int<1,3> | O30: 10 | P30: 1
C31: 2 | D31: 排水孔（管）位置 | G31: 允许偏差100mm | J31: @int<20,25>，@int<20,25>，@int<20,25>，@int<20,25>，@int<20,25>，@int<20,25>，@int<20,25>，@int<20,25>，@int<20,25>，@int<20,25> | O31: 10 | P31: 1
C32: 3 | D32: 基岩排水孔 | E32: 倾斜度 | F32: 孔深不小于8m | G32: 允许偏差1% | J32: / | O32: / | P32: /
F33: 孔深小于8m | G33: 允许偏差2% | J33: @int<1,3>，@int<1,3>，@int<1,3>，@int<1,3>，@int<1,3>，@int<1,3>，@int<1,3>，@int<1,3>，@int<1,3>，@int<1,3> | O33: 9 | P33: 0.9
E34: 深度 | G34: 允许偏差±0.5% | J34: @float.1<0.1,0.5>，@float.1<0.1,0.5>，@float.1<0.1,0.5>，@float.1<0.1,0.5>，@float.1<0.1,0.5>，@float.1<0.1,0.5>，@float.1<0.1,0.5>，@float.1<0.1,0.5>，@float.1<0.1,0.5>，@float.1<0.1,0.5> | O34: 8 | P34: 0.8
A35: 冷却及灌浆管路 | B35: 主控项目 | C35: 1 | D35: 管路安装 | G35: 安装牢固、可靠，接头不漏水、不漏气、无堵塞 | J35: 灌浆管安装牢固，不漏水、不漏气、无堵塞现象，检查结果完全符合质量要求。 | O35: / | P35: 1
B36: 一般项目 | C36: 1 | D36: 管路出口 | G36: 露出模板外300～500mm,妥善保护，有识别标志 | J36: @int<300,500>，@int<300,500>，@int<300,500>，@int<300,500>，@int<300,500> | O36: 4 | P36: 0.8
A37: 铁件 | B37: 主控项目 | C37: 1 | D37: 高程、方位、埋入深度及外露长度等 | G37: 符合设计要求 | J37: / | O37: / | P37: /
B38: 一般项目 | C38: 1 | D38: 铁件外观 | G38: 表面无锈皮、油污等 | J38: / | O38: / | P38: /
C39: 2 | D39: 锚筋钻孔位置 | F39: 梁、柱的锚筋 | G39: 允许偏差20mm | J39: / | O39: / | P39: /
F40: 钢筋网的锚筋 | G40: 允许偏差50mm | J40: / | O40: / | P40: /
C41: 3 | D41: 钻孔底部的孔径 | G41: 锚筋直径d+20mm | J41: / | O41: / | P41: /
C42: 4 | D42: 钻孔深度 | G42: 符合设计要求 | J42: / | O42: / | P42: /
...

Sheet 混凝土浇筑工序
A1: 布拖2024年高标准农田建设项目（增发国债）工程
A2: 表2.1.5 混凝土浇筑工序施工质量验收评定表（未找到对应设计值）
A3: 单位工程名称 | D3: =[1]普通混凝土单元!D3 -> 进水闸工程 | G3: 工序编号 | H3: /
A4: 分部工程名称 | D4: =[1]普通混凝土单元!D4 -> 闸室段 | G4: 施工单位 | H4: =[1]普通混凝土单元!G4 -> 四川华浩建筑工程有限公司
A5: 单元工程名称、部位 | D5: =[1]普通混凝土单元!D5 -> 2#闸墩，▽152.500～154.500m | G5: 施工日期 | H5: 年 月 日～ 年 月 日
A6: 项次 | C6: 检验项目 | E6: 质量要求 | H6: 检査记录 | I6: 合格数 | J6: 合格率
A7: 主控项目 | B7: 1 | C7: 入仓混凝土料 | E7: 无不合格料入仓。如有少量不合格料入仓，应及时处理至达到要求 | H7: 无不合格料入仓，检查结果完全符合质量要求。 | I7: / | J7: 1
B8: 2 | C8: 平仓分层 | E8: 厚度不大于振捣棒有效长度的90%，铺设均匀，分层清楚，无骨料集中现象 | H8: 厚度大约40～50cm，铺设均匀、分层清楚，无骨料集中现象，检查结果完全符合质量要求。 | I8: / | J8: 1
B9: 3 | C9: 混凝土振捣 | E9: 振捣器垂直插入下层5cm，有次序，间距、留振时间合理，无漏振、无超振 | H9: 振捣器垂直插入下层混凝土5cm左右，有次序，间距、留振时间合理，无漏振，无过振，检查结果完全符合质量要求。 | I9: / | J9: 1
B10: 4 | C10: 铺筑间歇时间 | E10: 符合要求，无初凝现象 | H10: 间歇时间符合要求，无初凝现象，检查结果完全符合质量要求。 | I10: / | J10: 1
B11: 5 | C11: 浇筑温度（指有温控要求的混凝土） | E11: 满足设计要求 | H11: / | I11: / | J11: /
B12: 6 | C12: 混凝土养护 | E12: 表面保持湿润；连续养护时间基本满足设计要求 | H12: 面层浇筑完成并初凝后及时开始养护，保持湿润，计划验收评定后继续养护到设计要求28d，检查结果完全符合质量要求。 | I12: / | J12: 1
A13: 一般项目 | B13: 1 | C13: 砂浆铺筑 | E13: 厚度宜为2～3cm，均匀平整，无漏铺 | H13: 铺筑均匀平整，无漏铺，@int<2,3>，@int<2,3>，@int<2,3>，@int<2,3>，@int<2,3>，@int<2,3>，@int<2,3>，@int<2,3>，@int<2,3>，@int<2,3>，@int<2,3>，@int<2,3>，@int<2,3>，@int<2,3>，@int<2,3>，@int<2,3>，@int<2,3>，@int<2,3>，@int<2,3>，@int<2,3> | I13: 16 | J13: 80
B14: 2 | C14: 积水和泌水 | E14: 无外部水流入，泌水排除及时 | H14: 无外水流入，无积水，少量泌水已及时排除，检查结果基本符合质量要求。 | I14: / | J14: 0.7
B15: 3 | C15: 插筋、管路等埋设件以及模板的保护 | E15: 保护好，符合设计要求 | H15: 抽查20处，有1处止水片有轻微位移，但不影响使用功能，其他保护完好，检查结果基本符合质量要求。 | I15: / | J15: 0.7
B16: 4 | C16: 混凝土表面保护 | E16: 保护时间、保温材料质量符合设计要求 | H16: / | I16: / | J16: /
B17: 5 | C17: 脱模 | E17: 脱模时间符合施工技术规范或设计要求 | H17: 已在达到设计强度（C30）后进行脱模，检查结果基本符合质量要求。 | I17: / | J17: 0.7
A18: 施工 单位 自评 意见 | C18: 主控项目检验点全部合格，一般项目逐项检验点的合格率均不小于__70___%，且不合格点不集中分布，
C19: 各项报验资料__符合___SL 632—2012的要求。
C20: 工序质量等级评定为：合格
C24: （签字，加盖公章）
C25: 年 月 日
A26: 监理 单位 复核 意见 | C26: 经复核，主控项目检验点全部合格，一般项目逐项检验点的合格率均不小于_____%，且不合格点不集中分布，
C27: 各项报验资料_____SL 632—2012的要求。
C28: 工序质量等级评定为：
C32: （签字，加盖公章）
C33: 年 月 日

Sheet 混凝土外观质量检查工序
A1: 布拖2024年高标准农田建设项目（增发国债）工程
A2: 表2.1.6 普通混凝土外观质量检查工序施工质量验收评定表（未找到对应设计值）
A3: 单位工程名称 | D3: 进水闸工程 | F3: 工序编号 | H3: /
A4: 分部工程名称 | D4: 闸室段 | F4: 施工单位 | H4: 四川华浩建筑工程有限公司
A5: 单元工程名称、部位 | D5: 2#闸墩，▽152.500～154.500m | F5: 施工日期 | H5: 年 月 日～ 年 月 日
A6: 项次 | C6: 检验项目 | E6: 质量要求 | G6: 检查记录 | M6: 合格数 | N6: 合格率
A7: 主控项目 | B7: 1 | C7: 有平整度要求的部位 | E7: 符合设计要求 | G7: / | M7: / | N7: /
B9: 2 | C9: 形体尺寸 | E9: 符合设计要求或允许偏差±20mm | F9: 设计值：17×30m | G9: 实测值：@float.3<17,17.02>×@float.2<29.98,30.02>，@float.3<17,17.02>×@float.2<29.98,30.02>，@float.3<17,17.02>×@float.2<29.98,30.02>，@float.3<17,17.02>×@float.2<29.98,30.02>，@float.3<17,17.02>×@float.2<29.98,30.02>，@float.3<17,17.02>×@float.2<29.98,30.02> | M9: 6 | N9: 1
B11: 3 | C11: 重要部位缺损 | E11: 不允许出现缺损 | G11: 无缺损，检查结果完全符合质量要求。 | M11: / | N11: 1
A12: 一般项目 | B12: 1 | C12: 表面平整度 | E12: 每2m偏差不大于8mm | G12: @float.1<0.4,7.6>，@float.1<0.4,7.6>，@float.1<0.4,7.6>，@float.1<0.4,7.6>，@float.1<0.4,7.6>，@float.1<0.4,7.6>，@float.1<0.4,7.6>，@float.1<0.4,7.6>，@float.1<0.4,7.6>，@float.1<0.4,7.6> | M12: 10 | N12: 1
E13: 设计值：
B14: 2 | C14: 麻面、蜂窝 | E14: 麻面、蜂窝累计面积不超过0.5%。经处理符合设计要求 | G14: 全面检查，无蜂窝，麻面，检查结果基本符合质量要求。 | M14: / | N14: 0.7
B15: 3 | C15: 孔洞 | E15: 单个面积不超过0.01㎡，且深度不超过骨料最大粒径。经处理符合设计要求 | G15: 无孔，检查结果基本符合质量要求。 | M15: / | N15: 0.7
B16: 4 | C16: 错台、跑模、掉角 | E16: 经处理符合设计要求 | G16: 无跑模、掉角，少量小错台，已磨平，检查结果基本符合质量要求。 | M16: / | N16: 0.7
B17: 5 | C17: 表面裂缝 | E17: 短小、深度不大于钢筋保护层厚度的表面裂缝经处理符合设计要求 | G17: 有2处小裂缝，在10mm以内，已按要求进行处理，检查结果基本符合质量要求。 | M17: / | N17: 0.7
A18: 施工 单位 自评 意见 | C18: 主控项目检验点全部合格，一般项目逐项检验点的合格率均不小于___70__%，且不合格点不集中分布，
C19: 各项报验资料__符合___SL 632—2012的要求。
C20: 工序质量等级评定为： | E20: 合格
C25: （签字，加盖公章）
C26: 年 月 日
A27: 监理 单位 复核 意见 | C27: 经复核，主控项目检验点全部合格，一般项目逐项检验点的合格率均不小于_____%，且不合格点不集中分布，
C28: 各项报验资料_____SL 632—2012的要求。
C29: 工序质量等级评定为：
C35: （签字，加盖公章）
C36: 年 月 日
